<?xml version="1.0"?>
<robot name="proste_ramie">

  <!-- ═══════════════════════════════════════════════════
       MATERIAŁY / KOLORY
  ═══════════════════════════════════════════════════ -->

  <!-- Stalowo-srebrny korpus -->
  <material name="steel">
    <color rgba="0.75 0.78 0.82 1.0"/>
  </material>

  <!-- Ciemnografitowe ramiona -->
  <material name="dark_metal">
    <color rgba="0.22 0.24 0.28 1.0"/>
  </material>

  <!-- Pomarańczowe akcenty (stawy, końcówka) -->
  <material name="accent_orange">
    <color rgba="0.95 0.45 0.05 1.0"/>
  </material>

  <!-- Żółto-zielony chwytak -->
  <material name="gripper_color">
    <color rgba="0.20 0.75 0.30 1.0"/>
  </material>

  <!-- Czarny pasek dekoracyjny -->
  <material name="black">
    <color rgba="0.10 0.10 0.12 1.0"/>
  </material>

  <!-- Jasny szary dla kul stawowych -->
  <material name="joint_ball">
    <color rgba="0.85 0.45 0.10 1.0"/>
  </material>


  <!-- ═══════════════════════════════════════════════════
       BAZA  (gruby walec + kula przejściowa)
  ═══════════════════════════════════════════════════ -->

  <link name="base_link">
    <!-- główna tarcza -->
    <visual>
      <origin xyz="0 0 0" rpy="0 0 0"/>
      <geometry>
        <cylinder length="0.16" radius="0.36"/>
      </geometry>
      <material name="steel"/>
    </visual>
    <!-- pierścień ozdobny (węższy, wyżej) -->
    <visual>
      <origin xyz="0 0 0.11" rpy="0 0 0"/>
      <geometry>
        <cylinder length="0.06" radius="0.24"/>
      </geometry>
      <material name="accent_orange"/>
    </visual>
    <!-- kula przejścia do link1 -->
    <visual>
      <origin xyz="0 0 0.14" rpy="0 0 0"/>
      <geometry>
        <sphere radius="0.14"/>
      </geometry>
      <material name="joint_ball"/>
    </visual>

    <collision>
      <origin xyz="0 0 0" rpy="0 0 0"/>
      <geometry>
        <cylinder length="0.16" radius="0.36"/>
      </geometry>
    </collision>
    <inertial>
      <mass value="80"/>
      <inertia ixx="4.8" ixy="0" ixz="0" iyy="4.8" iyz="0" izz="6.4"/>
    </inertial>
  </link>


  <!-- ═══════════════════════════════════════════════════
       JOINT 1 – obrót wokół Z (baza → link1)
  ═══════════════════════════════════════════════════ -->

  <joint name="joint1" type="revolute">
    <parent link="base_link"/>
    <child  link="link1"/>
    <origin xyz="0 0 0.14" rpy="0 0 0"/>
    <axis   xyz="0 0 2"/>
    <limit  lower="-2.618" upper="2.618" effort="300" velocity="1.2"/>
    <dynamics damping="8" friction="1.6"/>
  </joint>


  <!-- ═══════════════════════════════════════════════════
       LINK 1 – pierwsze (najdłuższe) ramię
  ═══════════════════════════════════════════════════ -->

  <link name="link1">
    <!-- główny trzon -->
    <visual>
      <origin xyz="0 0 0.19" rpy="0 0 0"/>
      <geometry>
        <cylinder length="0.38" radius="0.09"/>
      </geometry>
      <material name="dark_metal"/>
    </visual>
    <!-- ozdobny środkowy pierścień -->
    <visual>
      <origin xyz="0 0 0.19" rpy="0 0 0"/>
      <geometry>
        <cylinder length="0.08" radius="0.11"/>
      </geometry>
      <material name="accent_orange"/>
    </visual>
    <!-- kula u góry (przejście do joint2) -->
    <visual>
      <origin xyz="0 0 0.39" rpy="0 0 0"/>
      <geometry>
        <sphere radius="0.11"/>
      </geometry>
      <material name="joint_ball"/>
    </visual>

    <collision>
      <origin xyz="0 0 0.19" rpy="0 0 0"/>
      <geometry>
        <cylinder length="0.38" radius="0.09"/>
      </geometry>
    </collision>
    <inertial>
      <origin xyz="0 0 0.19" rpy="0 0 0"/>
      <mass value="16"/>
      <inertia ixx="0.96" ixy="0" ixz="0" iyy="0.96" iyz="0" izz="0.128"/>
    </inertial>
  </link>


  <!-- ═══════════════════════════════════════════════════
       JOINT 2 – zgięcie wokół Y
  ═══════════════════════════════════════════════════ -->

  <joint name="joint2" type="revolute">
    <parent link="link1"/>
    <child  link="link2"/>
    <origin xyz="0 0 0.39" rpy="0 0 0"/>
    <axis   xyz="0 2 0"/>
    <limit  lower="-1.57" upper="1.57" effort="240" velocity="1.2"/>
    <dynamics damping="6.4" friction="1.6"/>
  </joint>


  <!-- ═══════════════════════════════════════════════════
       LINK 2 – środkowe ramię
  ═══════════════════════════════════════════════════ -->

  <link name="link2">
    <visual>
      <origin xyz="0 0 0.28" rpy="0 0 0"/>
      <geometry>
        <cylinder length="0.52" radius="0.072"/>
      </geometry>
      <material name="steel"/>
    </visual>
    <!-- ozdobny pierścień -->
    <visual>
      <origin xyz="0 0 0.28" rpy="0 0 0"/>
      <geometry>
        <cylinder length="0.06" radius="0.092"/>
      </geometry>
      <material name="black"/>
    </visual>
    <!-- kula u góry -->
    <visual>
      <origin xyz="0 0 0.54" rpy="0 0 0"/>
      <geometry>
        <sphere radius="0.088"/>
      </geometry>
      <material name="joint_ball"/>
    </visual>

    <collision>
      <origin xyz="0 0 0.28" rpy="0 0 0"/>
      <geometry>
        <cylinder length="0.52" radius="0.072"/>
      </geometry>
    </collision>
    <inertial>
      <origin xyz="0 0 0.28" rpy="0 0 0"/>
      <mass value="9.6"/>
      <inertia ixx="0.32" ixy="0" ixz="0" iyy="0.32" iyz="0" izz="0.064"/>
    </inertial>
  </link>


  <!-- ═══════════════════════════════════════════════════
       JOINT 3 – zgięcie wokół Y
  ═══════════════════════════════════════════════════ -->

  <joint name="joint3" type="revolute">
    <parent link="link2"/>
    <child  link="link3"/>
    <origin xyz="0 0 0.54" rpy="0 0 0"/>
    <axis   xyz="0 2 0"/>
    <limit  lower="-1.57" upper="1.57" effort="160" velocity="1.5"/>
    <dynamics damping="4.8" friction="1.28"/>
  </joint>


  <!-- ═══════════════════════════════════════════════════
       LINK 3 – krótkie ramię przed przegubem
  ═══════════════════════════════════════════════════ -->

  <link name="link3">
    <visual>
      <origin xyz="0 0 0.18" rpy="0 0 0"/>
      <geometry>
        <cylinder length="0.32" radius="0.056"/>
      </geometry>
      <material name="dark_metal"/>
    </visual>
    <!-- kula u góry -->
    <visual>
      <origin xyz="0 0 0.34" rpy="0 0 0"/>
      <geometry>
        <sphere radius="0.072"/>
      </geometry>
      <material name="joint_ball"/>
    </visual>

    <collision>
      <origin xyz="0 0 0.18" rpy="0 0 0"/>
      <geometry>
        <cylinder length="0.32" radius="0.056"/>
      </geometry>
    </collision>
    <inertial>
      <origin xyz="0 0 0.18" rpy="0 0 0"/>
      <mass value="4.8"/>
      <inertia ixx="0.16" ixy="0" ixz="0" iyy="0.16" iyz="0" izz="0.032"/>
    </inertial>
  </link>


  <!-- ═══════════════════════════════════════════════════
       JOINT WRIST – przegub nadgarstka
  ═══════════════════════════════════════════════════ -->

  <joint name="joint_wrist" type="revolute">
    <parent link="link3"/>
    <child  link="wrist_link"/>
    <origin xyz="0 0 0.34" rpy="0 0 0"/>
    <axis   xyz="0 2 0"/>
    <limit  lower="-1.57" upper="1.57" effort="100" velocity="2.0"/>
    <dynamics damping="3.2" friction="0.8"/>
  </joint>


  <!-- ═══════════════════════════════════════════════════
       WRIST LINK – walec nadgarstka
  ═══════════════════════════════════════════════════ -->

  <link name="wrist_link">
    <!-- walec -->
    <visual>
      <origin xyz="0 0 0.08" rpy="0 0 0"/>
      <geometry>
        <cylinder length="0.14" radius="0.044"/>
      </geometry>
      <material name="steel"/>
    </visual>
    <!-- pomarańczowa końcówka / palma chwytaka -->
    <visual>
      <origin xyz="0 0 0.16" rpy="0 0 0"/>
      <geometry>
        <box size="0.2 0.12 0.036"/>
      </geometry>
      <material name="accent_orange"/>
    </visual>

    <collision>
      <origin xyz="0 0 0.08" rpy="0 0 0"/>
      <geometry>
        <cylinder length="0.14" radius="0.044"/>
      </geometry>
    </collision>
    <inertial>
      <origin xyz="0 0 0.08" rpy="0 0 0"/>
      <mass value="2"/>
      <inertia ixx="0.032" ixy="0" ixz="0" iyy="0.032" iyz="0" izz="0.032"/>
    </inertial>
  </link>


  <!-- ═══════════════════════════════════════════════════
       JOINT stały wrist → gripper
  ═══════════════════════════════════════════════════ -->

  <joint name="joint_gripper_fix" type="fixed">
    <parent link="wrist_link"/>
    <child  link="gripper_link"/>
    <origin xyz="0 0 0.18" rpy="0 0 0"/>
  </joint>


  <!-- ═══════════════════════════════════════════════════
       GRIPPER LINK – palma + dwa palce (szczęki)
  ═══════════════════════════════════════════════════ -->

  <link name="gripper_link">

    <!-- Lewy palec -->
    <visual>
      <origin xyz="-0.07 0 0.06" rpy="0 0 0"/>
      <geometry>
        <box size="0.032 0.036 0.12"/>
      </geometry>
      <material name="gripper_color"/>
    </visual>
    <!-- Lewy szpic palca (ścięty) -->
    <visual>
      <origin xyz="-0.07 0 0.13" rpy="0 0 0"/>
      <geometry>
        <box size="0.02 0.028 0.02"/>
      </geometry>
      <material name="black"/>
    </visual>

    <!-- Prawy palec -->
    <visual>
      <origin xyz="0.07 0 0.06" rpy="0 0 0"/>
      <geometry>
        <box size="0.032 0.036 0.12"/>
      </geometry>
      <material name="gripper_color"/>
    </visual>
    <!-- Prawy szpic palca -->
    <visual>
      <origin xyz="0.07 0 0.13" rpy="0 0 0"/>
      <geometry>
        <box size="0.02 0.028 0.02"/>
      </geometry>
      <material name="black"/>
    </visual>

    <!-- Kolizja uproszczona — jedna duża skrzynka obejmująca oba palce -->
    <collision>
      <origin xyz="0 0 0.06" rpy="0 0 0"/>
      <geometry>
        <box size="0.2 0.044 0.14"/>
      </geometry>
    </collision>
    <inertial>
      <origin xyz="0 0 0.06" rpy="0 0 0"/>
      <mass value="1.2"/>
      <inertia ixx="0.032" ixy="0" ixz="0" iyy="0.032" iyz="0" izz="0.032"/>
    </inertial>
  </link>

</robot>
